Workbook

Sheet 1. RAB PADI 1 Ha
A1: RENCANA ANGGARAN BIAYA (RAB)
A2: USAHATANI PADI 1 HA
A3: MUSIM TANAM 3 (AGUSTUS - DESEMBER 2026)
A6: NO | B6: URAIAN | C6: VOLUME | D6: SATUAN | E6: HARGA SATUAN (RP) | F6: MT 3 (Gadu)
A7: A | B7: BIAYA VARIABEL
A8: I | B8: SAPRODI
A9: 1 | B9: Benih | C9: 25 | D9: Kg | E9: 16500 | F9: =C9*E9 -> 412500
A10: 2 | B10: Pupuk NPK Subsidi | C10: 140 | D10: Kg | E10: =115000/50 -> 2300 | F10: =C10*E10 -> 322000
A11: 3 | B11: Pupuk Urea Subsidi | C11: 230 | D11: Kg | E11: =112500/50 -> 2250 | F11: =C11*E11 -> 517500
A12: 4 | B12: Herbisida (kontak) | C12: 5 | D12: Liter | E12: 60000 | F12: =C12*E12 -> 300000
A13: 5 | B13: Dolomit @40kg | C13: 7 | D13: Sak | E13: 16000 | F13: =C13*E13 -> 112000
A14: 6 | B14: Pestisida (Obat HPT) | C14: 1 | D14: Paket | E14: 505000 | F14: =C14*E14 -> 505000
A15: 7 | B15: Karung | C15: 140 | D15: Lembar | E15: 2000 | F15: =C15*E15 -> 280000
B16: TOTAL | F16: =SUM(F9:F15) -> 2449000
A18: II | B18: JASA ALSINTAN
A19: 1 | B19: Jasa Pengolahan Tanah (TR 2) 6 - 8 Jam | C19: 1 | D19: Paket | E19: 2100000 | F19: =C19*E19 -> 2100000
A20: 2 | B20: Jasa Penanaman (Transplanter) 5 - 6 Jam | C20: 1 | D20: Paket | E20: =300000*7 -> 2100000 | F20: =C20*E20 -> 2100000
A21: 3 | B21: Jasa Panen (Combine Harvester) 4 - 5 Jam | C21: 1 | D21: Paket | E21: =350000*7 -> 2450000 | F21: =C21*E21 -> 2450000
A22: 4 | B22: Jasa Pompa Air | C22: 1 | D22: Paket | E22: 1500000 | F22: =C22*E22 -> 1500000
B23: TOTAL | F23: =SUM(F19:F22) -> 8150000
A25: III | B25: TENAGA KERJA
A26: 1 | B26: Persemaian sistem Dapog | C26: 1 | D26: HOK | E26: 120000 | F26: =C26*E26 -> 120000
A27: 2 | B27: Pengapuran | C27: 2 | D27: HOK | E27: 120000 | F27: =C27*E27 -> 240000
A28: 3 | B28: Sulam | C28: 3 | D28: HOK | E28: 120000 | F28: =C28*E28 -> 360000
A29: 4 | B29: Penyiangan Herbisida | C29: 4 | D29: HOK | E29: 120000 | F29: =C29*E29 -> 480000
A30: 5 | B30: Pemupukan | C30: 4 | D30: HOK | E30: 120000 | F30: =C30*E30 -> 480000
A31: 6 | B31: Pengendalian OPT | C31: 8 | D31: HOK | E31: 120000 | F31: =C31*E31 -> 960000
A32: 7 | B32: Pengairan | C32: 6 | D32: HOK | E32: 120000 | F32: =C32*E32 -> 720000
B33: TOTAL | C33: =SUM(C26:C32) -> 28 | D33: HOK | E33: 120000 | F33: =C33*E33 -> 3360000
B35: TOTAL BIAYA VARIABEL | F35: =SUM(F16+F23+F33) -> 13959000
A37: B | B37: BIAYA TETAP
A38: 1 | B38: Sewa lahan | C38: 1 | D38: Ha/Tahun | E38: 21000000 | F38: =E38/3 -> 7000000
B39: TOTAL TETAP | F39: =SUM(F38) -> 7000000
A41: C | B41: LAIN - LAIN
A42: 1 | B42: Iuran Pengairan | C42: 1 | D42: Paket | E42: 1000000 | F42: 1000000
A43: 2 | B43: Transport | C43: 1 | D43: Paket | E43: 200000 | F43: =C43*E43 -> 200000
B45: TOTAL BIAYA LAIN - LAIN | F45: =SUM(F42:F43) -> 1200000
A47: D | B47: TOTAL BIAYA PRODUKSI | F47: =F35+F39+F45 -> 22159000
A49: E | B49: ESTIMASI PENDAPATAN
B50: Produksi | C50: 7000 | D50: kg
...

Sheet 2. Catatan Transaksi Harian
A1: CATATAN TRANSAKSI HARIAN
A2: USAHATANI PADI 1 HA PADA MT 3 ( AGUSTUS - DESEMBER 2026)
A4: Tanggal | B4: Uraian Transaksi | C4: Volume | D4: Satuan | E4: Harga Satuan (Rp) | F4: Pengeluaran (Rp) | G4: Pemasukan (Rp)
A5: 01 Ags | B5: Pembelian benih padi | C5: 25 | D5: Kg | E5: 16500 | F5: 412500 | G5: -
A6: 02 Ags | B6: Pembelian herbisida persiapan lahan | C6: 3 | D6: Liter | E6: 60000 | F6: 180000 | G6: -
A7: 03 Ags | B7: Pembelian dolomit | C7: 7 | D7: Sak | E7: 16000 | F7: 112000 | G7: -
A8: 05 Ags | B8: Pembayaran jasa pengolahan tanah (TR 2) | C8: 1 | D8: Paket | E8: 2100000 | F8: 2100000 | G8: -
A9: 08 Ags | B9: Pembayaran upah pengapuran | C9: 2 | D9: HOK | E9: 120000 | F9: 240000 | G9: -
A10: 10 Ags | B10: Pembayaran upah persemaian sistem dapog | C10: 1 | D10: HOK | E10: 120000 | F10: 120000 | G10: -
A11: 15 Ags | B11: Pembelian pupuk NPK subsidi | C11: 140 | D11: Kg | E11: 2300 | F11: 322000 | G11: -
A12: 15 Ags | B12: Pembelian pupuk Urea subsidi | C12: 230 | D12: Kg | E12: 2250 | F12: 517500 | G12: -
A13: 20 Ags | B13: Pembayaran jasa penanaman menggunakan transplanter | C13: 1 | D13: Paket | E13: 2100000 | F13: 2100000 | G13: -
A14: 25 Ags | B14: Pembayaran upah pemupukan I | C14: 2 | D14: HOK | E14: 120000 | F14: 240000 | G14: -
A15: 28 Ags | B15: Pembayaran upah pengairan I | C15: 1 | D15: HOK | E15: 120000 | F15: 120000 | G15: -
A16: 46270 | B16: Pembelian herbisida penyiangan | C16: 2 | D16: Liter | E16: 60000 | F16: 120000 | G16: -
A17: 46270 | B17: Pembayaran upah penyiangan herbisida I | C17: 2 | D17: HOK | E17: 120000 | F17: 240000 | G17: -
A18: 46275 | B18: Pembelian pestisida/obat HPT | C18: 1 | D18: Paket | E18: 250000 | F18: 250000 | G18: -
A19: 46275 | B19: Pembayaran upah pengendalian OPT I | C19: 1 | D19: HOK | E19: 120000 | F19: 120000 | G19: -
A20: 46285 | B20: Pembayaran upah penyulaman tanaman | C20: 3 | D20: HOK | E20: 120000 | F20: 360000 | G20: -
A21: 46290 | B21: Pembayaran upah pengendalian OPT II | C21: 1 | D21: HOK | E21: 120000 | F21: 120000 | G21: -
A22: 46295 | B22: Pembayaran upah pengairan II | C22: 1 | D22: HOK | E22: 120000 | F22: 120000 | G22: -
A23: 05 Okt | B23: Pembayaran upah pemupukan II | C23: 2 | D23: HOK | E23: 120000 | F23: 240000 | G23: -
A24: 10 Okt | B24: Pembayaran upah pengendalian OPT III | C24: 1 | D24: HOK | E24: 120000 | F24: 120000 | G24: -
A25: 15 Okt | B25: Pembayaran upah pengairan III | C25: 1 | D25: HOK | E25: 120000 | F25: 120000 | G25: -
A26: 25 Okt | B26: Pembayaran upah penyiangan herbisida II | C26: 2 | D26: HOK | E26: 120000 | F26: 240000 | G26: -
A27: 30 Okt | B27: Pembayaran upah pengendalian OPT IV | C27: 1 | D27: HOK | E27: 120000 | F27: 120000 | G27: -
A28: 46331 | B28: Pembelian pestisida/obat HPT tambahan | C28: 1 | D28: Paket | E28: 255000 | F28: 255000 | G28: -
A29: 46331 | B29: Pembayaran upah pengairan IV | C29: 1 | D29: HOK | E29: 120000 | F29: 120000 | G29: -
A30: 46336 | B30: Pembayaran upah pengendalian OPT V | C30: 1 | D30: HOK | E30: 120000 | F30: 120000 | G30: -
A31: 46341 | B31: Pembayaran jasa pompa air | C31: 1 | D31: Paket | E31: 1500000 | F31: 1500000 | G31: -
A32: 46346 | B32: Pembayaran iuran pengairan | C32: 1 | D32: Paket | E32: 1000000 | F32: 1000000 | G32: -
A33: 46351 | B33: Pembayaran upah pengendalian OPT VI | C33: 1 | D33: HOK | E33: 120000 | F33: 120000 | G33: -
A34: 46356 | B34: Pembayaran upah pengairan V | C34: 1 | D34: HOK | E34: 120000 | F34: 120000 | G34: -
A35: 05 Des | B35: Pembelian karung gabah | C35: 140 | D35: Lembar | E35: 2000 | F35: 280000 | G35: -
A36: 10 Des | B36: Pembayaran upah pengendalian OPT VII | C36: 1 | D36: HOK | E36: 120000 | F36: 120000 | G36: -
A37: 12 Des | B37: Pembayaran biaya transport hasil panen | C37: 1 | D37: Paket | E37: 200000 | F37: 200000 | G37: -
A38: 15 Des | B38: Pembayaran jasa panen combine harvester | C38: 1 | D38: Paket | E38: 2450000 | F38: 2450000 | G38: -
A39: 18 Des | B39: Pembayaran upah pengendalian OPT VIII | C39: 1 | D39: HOK | E39: 120000 | F39: 120000 | G39: -
A40: 20 Des | B40: Pembayaran upah pengairan VI | C40: 1 | D40: HOK | E40: 120000 | F40: 120000 | G40: -
A41: 25 Des | B41: Penjualan gabah kering panen (GKP) | C41: 7000 | D41: Kg | E41: 6500 | F41: - | G41: 45500000

Sheet 3. Laporan laba rugi
G3: Laba/Rugi
D6: Jenis | G6: Jumlah | I6: Jenis | K6: Jumlah
D7: Pengeluaran | I7: Pendapatan
E8: Input Usaha Tani | J8: Penjualan Padi (GKP) | K8: ='1. RAB PADI 1 Ha'!F52 -> 45500000
F9: Benih | G9: ='1. RAB PADI 1 Ha'!F9 -> 412500
F10: NPK | G10: ='1. RAB PADI 1 Ha'!F10 -> 322000
F11: Urea | G11: ='1. RAB PADI 1 Ha'!F11 -> 517500
F12: Herbisida | G12: ='1. RAB PADI 1 Ha'!F12 -> 300000 | J12: Total Pendapatan | K12: =SUM(K8:K10) -> 45500000
F13: Dolomit | G13: ='1. RAB PADI 1 Ha'!F13 -> 112000
F14: Pestisida | G14: ='1. RAB PADI 1 Ha'!F14 -> 505000
F15: Karung | G15: ='1. RAB PADI 1 Ha'!F15 -> 280000
D16: Sub-total | G16: =SUM(G9:G15) -> 2449000
I17: Jenis | K17: Jumlah
E18: Tenaga Kerja
F19: Tenaga Kerja Eksternal | G19: ='1. RAB PADI 1 Ha'!F33 -> 3360000 | I19: Total Pendapatan | K19: =K12 -> 45500000
D21: Sub-total | G21: =SUM(G19:G19) -> 3360000
I22: Total Pengeluaran | K22: =G39 -> 22159000
E23: Jasa Alsintan
F24: Olah Lahan (TR2) | G24: ='1. RAB PADI 1 Ha'!F19 -> 2100000 | J24: Laba/Rugi | K24: =K19-K22 -> 23341000
F25: Tanam (Transplanter) | G25: ='1. RAB PADI 1 Ha'!F20 -> 2100000
F26: Panen (Combine) | G26: ='1. RAB PADI 1 Ha'!F21 -> 2450000
F27: Pompa Air | G27: ='1. RAB PADI 1 Ha'!F22 -> 1500000
D29: Sub-total | G29: =SUM(G24:G27) -> 8150000
E31: Lain-lain
F32: Iuran Pengairan | G32: ='1. RAB PADI 1 Ha'!F42 -> 1000000
F33: Transport | G33: ='1. RAB PADI 1 Ha'!F43 -> 200000
F34: Sewa Lahan | G34: ='1. RAB PADI 1 Ha'!F38 -> 7000000
D36: Sub-total | G36: =SUM(G32:G34) -> 8200000 | O36: =K33/60 -> 0
D39: Total Pengeluaran | G39: =G16+G21+G29+G36 -> 22159000

Sheet 4. Arus kas
E4: Laporan Kas - Kegiatan Usaha Tani Padi Non Rawa 1 Ha
C7: Deskripsi | F7: JULI | G7: AGUSTUS | H7: SEPTEMBER | I7: OKTOBER | J7: NOPEMBER | K7: DESEMBER | L7: Total
C8: Pendapatan
D9: Hasil Penjualan | K9: ='3. Laporan laba rugi'!K12 -> 45500000 | L9: =SUM(F9:K9) -> 45500000
K10: ='[1]5. LABA RUGI'!K13 -> 0 | L10: ='[1]5. LABA RUGI'!L13 -> 0
E11: Total Pendapatan | F11: =SUM(F10:F10) -> 0 | G11: =SUM(G10:G10) -> 0 | H11: =SUM(H10:H10) -> 0 | I11: =SUM(I10:I10) -> 0 | J11: =SUM(J10:J10) -> 0 | K11: =SUM(K9:K10) -> 45500000 | L11: =SUM(L9:L10) -> 45500000
C12: Pengeluaran
D13: Input usaha tani
E14: Benih | G14: ='3. Laporan laba rugi'!G9 -> 412500 | L14: =SUM(F14:K14) -> 412500
E15: NPK | G15: ='3. Laporan laba rugi'!G10 -> 322000 | L15: =SUM(F15:K15) -> 322000
E16: Urea | G16: ='3. Laporan laba rugi'!G11 -> 517500 | L16: =SUM(F16:K16) -> 517500
E17: Herbisida | G17: 180000 | H17: 120000 | L17: =SUM(F17:K17) -> 300000
E18: Dolomit | G18: ='3. Laporan laba rugi'!G13 -> 112000 | H18: 250000 | J18: 255000 | L18: =SUM(F18:K18) -> 617000
E19: Pestisida | K19: 280000 | L19: =SUM(F19:K19) -> 280000
E20: Karung | L20: =SUM(F20:K20) -> 0
E21: Sub-total | G21: =SUM(G14:G19) -> 1544000 | H21: =SUM(H14:H19) -> 370000 | I21: =SUM(I14:I19) -> 0 | J21: =SUM(J14:J19) -> 255000 | K21: =SUM(K14:K19) -> 280000 | L21: =SUM(G21:K21) -> 2449000
D23: Biaya Tenaga Kerja
E24: Tenaga kerja | G24: 720000 | H24: 960000 | I24: 840000 | J24: 480000 | K24: 360000 | L24: =SUM(G24:K24) -> 3360000
E26: Sub-total | G26: =SUM(G24:G25) -> 720000 | H26: =SUM(H24:H25) -> 960000 | I26: =SUM(I24:I25) -> 840000 | J26: =SUM(J24:J25) -> 480000 | K26: =SUM(K24:K25) -> 360000 | L26: =SUM(G26:K26) -> 3360000
D28: Jasa Alsintan
E29: Olah Lahan (TR2) | G29: ='3. Laporan laba rugi'!G24 -> 2100000 | L29: =SUM(G29:K29) -> 2100000
E30: Tanam (Transplanter) | G30: ='3. Laporan laba rugi'!G25 -> 2100000 | L30: =SUM(G30:K30) -> 2100000
E31: Panen (Combine) | K31: ='3. Laporan laba rugi'!G26 -> 2450000 | L31: =SUM(G31:K31) -> 2450000
E32: Pompa Air | J32: ='3. Laporan laba rugi'!G27 -> 1500000 | L32: =SUM(G32:K32) -> 1500000
E33: Sub-total | G33: =SUM(G29:G32) -> 4200000 | H33: =SUM(H29:H32) -> 0 | I33: =SUM(I29:I32) -> 0 | J33: =SUM(J29:J32) -> 1500000 | K33: =SUM(K29:K32) -> 2450000 | L33: =SUM(L29:L32) -> 8150000
D35: Lain - lain
E36: Transport | K36: 200000 | L36: =SUM(F36:K36) -> 200000
E37: Rafia | J37: 1000000 | L37: =SUM(F37:K37) -> 1000000
E38: Sewa Lahan | G38: ='3. Laporan laba rugi'!G34 -> 7000000
E40: Sub-total | G40: =SUM(G36:G39) -> 7000000 | H40: =SUM(H36:H39) -> 0 | I40: =SUM(I36:I39) -> 0 | J40: =SUM(J36:J39) -> 1000000 | K40: =SUM(K36:K39) -> 200000 | L40: =SUM(L36:L39) -> 1200000
E42: Total Pengeluaran | G42: =G21+G26+G33+G40 -> 13464000 | H42: =H21+H26+H33+H40 -> 1330000 | I42: =I21+I26+I33+I40 -> 840000 | J42: =J21+J26+J33+J40 -> 3235000 | K42: =K21+K26+K33+K40 -> 3290000 | L42: =L21+L26+L33+L40 -> 15159000
E44: Arus Kas | G44: =0-G42 -> -13464000 | H44: =0-H42 -> -1330000 | I44: =0-I42 -> -840000 | J44: =0-J42 -> -3235000 | K44: =K11-K42 -> 42210000 | L44: =SUM(G44:K44) -> 23341000

Sheet 5. Arus Kas Pasca Pembiayaan
D3: Kebutuhan Modal Kerja - Pembiayaan - Arus Kas Kegiatan Usahatani Setelah Pembiayaan (Pinjaman)
C6: Arus Kas Kegiatan Usaha Tani sebelum Pembiayaan (pinjaman)
C7: Deskripsi | E7: JULI | G7: AGUSTUS | H7: SEPTEMBER | I7: OKTOBER | J7: NOPEMBER | K7: DESEMBER | L7: Total
C9: Arus kas bulanan Kegiatan Usaha Tani | G9: ='4. Arus kas'!G44 -> -13464000 | H9: ='4. Arus kas'!H44 -> -1330000 | I9: ='4. Arus kas'!I44 -> -840000 | J9: ='4. Arus kas'!J44 -> -3235000 | K9: ='4. Arus kas'!K44 -> 42210000 | L9: ='4. Arus kas'!L44 -> 23341000
E12: Kebutuhan pembiayaan
E13: Deskripsi | I13: Total
E14: Kebutuhan pembiayaan
F15: Modal kerja yang dibutuhkan | I15: =-J15 -> 18869000 | J15: =SUM(G9:J9) -> -18869000
F16: Modal sendiri dari BP | I16: 3869000
F18: Sumber Pendanaan lain yang bisa di pinjam | I18: =I15-I16 -> 15000000
E20: Jangka waktu modal kerja (dalam bulan) | I20: 6
E22: Pinjaman ber subsidi - KUR
F23: Suku Bunga Pinjaman Tahunan | I23: 0.06
F24: Suku bunga per musim tanam | I24: 0.03
F25: Bunga yang harus dibayar | I25: =I18*3% -> 450000
F26: Sumber dana lain yang harus di bayar | I26: =I18+I25 -> 15450000
C29: Arus Kas - Kegiatan usaha tani setelah pembiayaan (pinjaman)
C30: Deskripsi | E30: JULI | G30: AGUSTUS | H30: SEPTEMBER | I30: OKTOBER | J30: NOPEMBER | K30: DESEMBER | L30: Total
C31: Arus kas dari kegiatan keuangan
D32: Modal sendiri dari BP | E32: =I16 -> 3869000 | L32: =SUM(E32:K32) -> 3869000
D33: Pinjaman yang diterima | E33: =I18 -> 15000000 | L33: =SUM(E33:K33) -> 15000000 | P33: =SUM(L32:L34) -> 3419000
D34: Pembayaran Pinjaman | K34: =-I26 -> -15450000 | L34: =SUM(E34:K34) -> -15450000
L35: =SUM(E35:K35) -> 0
D36: Arus kas dari kegiatan keuangan | E36: =SUM(E32:F35) -> 18869000 | G36: =SUM(G32:H35) -> 0 | I36: =SUM(I32:J35) -> 0 | K36: =SUM(K32:K34) -> -15450000
D38: Arus kas bulanan Kegiatan Usaha tani sebelum pembiayaan | E38: =E9 -> 0 | G38: =G9 -> -13464000 | H38: =H9 -> -1330000 | I38: =I9 -> -840000 | J38: =J9 -> -3235000 | K38: =K9 -> 42210000 | L38: =SUM(E38:K38) -> 23341000
D40: Arus kas Kumulatif Kegiatan Usaha Tani setelah pembiayaan | E40: =E36+E38 -> 18869000 | G40: =E40+G38 -> 5405000 | H40: =G40+H38 -> 4075000 | I40: =H40+I38 -> 3235000 | J40: =I40+J38 -> 0 | K40: =J40+K36+K38 -> 26760000 | L40: =K40-L32 -> 22891000
